<?xml version="1.0"?>
<robot  name="Franka_research3" >
 <link  name="world" />
 <joint  name="world_Franka_research3_joint"  type="fixed" >
  <origin  rpy="0 0 0"  xyz="0 0 0" />
  <parent  link="world" />
  <child  link="Franka_research3_link_0" />
 </joint>
 <link  name="Franka_research3_link_0" >
  <inertial >
   <origin  rpy="0.0 0.0 0.0"  xyz="0.0 0.0 0.0" />
   <mass  value="0" />
   <inertia  izz="0"  iyy="0"  ixz="0"  ixx="0"  iyz="0"  ixy="0" />
  </inertial>
  <visual >
   <origin  xyz="0.0 0.0 0.0" />
  </visual>
  <collision >
   <origin  xyz="0.0 0.0 0.0" />
  </collision>
 </link>
 <joint  name="Franka_research3_joint_1"  type="revolute" >
  <parent  link="Franka_research3_link_0" />
  <child  link="Franka_research3_link_1" />
  <origin  rpy="0.0 -0.0 0.0"  xyz="0.0 0.0 0.141" />
  <axis  xyz="0 0 1" />
  <limit  velocity="10"  lower="-2.9"  upper="2.9"  effort="300" />
 </joint>
 <link  name="Franka_research3_link_1" >
  <inertial >
   <origin  rpy="0.0 0.0 0.0"  xyz="0.0 0.0 0.0" />
   <mass  value="1.95" />
   <inertia  izz="0"  iyy="0"  ixz="0"  ixx="0"  iyz="0"  ixy="0" />
  </inertial>
  <visual >
   <origin  xyz="0.0 -0.02 0.0" />
  </visual>
  <collision >
   <origin  xyz="0.0 -0.02 0.0" />
  </collision>
 </link>
 <joint  name="Franka_research3_joint_2"  type="revolute" >
  <parent  link="Franka_research3_link_1" />
  <child  link="Franka_research3_link_2" />
  <origin  rpy="-1.5707963267948966 0.0 0.0"  xyz="-9e-06 -0.0005 0.192025" />
  <axis  xyz="0 0 1" />
  <limit  velocity="10"  lower="-1.83"  upper="1.83"  effort="300" />
 </joint>
 <link  name="Franka_research3_link_2" >
  <inertial >
   <origin  rpy="0.0 0.0 0.0"  xyz="0.0 0.0 0.0" />
   <mass  value="3.42" />
   <inertia  izz="0"  iyy="0"  ixz="0"  ixx="0"  iyz="0"  ixy="0" />
  </inertial>
  <visual >
   <origin  xyz="0.13 0.0 0.1157" />
  </visual>
  <collision >
   <origin  xyz="0.13 0.0 0.1157" />
  </collision>
 </link>
 <joint  name="Franka_research3_joint_3"  type="revolute" >
  <parent  link="Franka_research3_link_2" />
  <child  link="Franka_research3_link_3" />
  <origin  rpy="1.5707963267948966 0.0 0.0"  xyz="0.0 -0.192974 0.0" />
  <axis  xyz="0 0 1" />
  <limit  velocity="10"  lower="-2.9"  upper="2.9"  effort="300" />
 </joint>
 <link  name="Franka_research3_link_3" >
  <inertial >
   <origin  rpy="0.0 0.0 0.0"  xyz="0.0 0.0 0.0" />
   <mass  value="1.437" />
   <inertia  izz="0"  iyy="0"  ixz="0"  ixx="0"  iyz="0"  ixy="0" />
  </inertial>
  <visual >
   <origin  xyz="0.05 0.0 0.0238" />
  </visual>
  <collision >
   <origin  xyz="0.05 0.0 0.0238" />
  </collision>
 </link>
 <joint  name="Franka_research3_joint_4"  type="revolute" >
  <parent  link="Franka_research3_link_3" />
  <child  link="Franka_research3_link_4" />
  <origin  rpy="1.5707963267948966 0.0 0.0"  xyz="0.082504 -0.0005 0.122952" />
  <axis  xyz="0 0 1" />
  <limit  velocity="10"  lower="-3.07"  upper="-0.12"  effort="300" />
 </joint>
 <link  name="Franka_research3_link_4" >
  <inertial >
   <origin  rpy="0.0 0.0 0.0"  xyz="0.0 0.0 0.0" />
   <mass  value="0.871" />
   <inertia  izz="0"  iyy="0"  ixz="0"  ixx="0"  iyz="0"  ixy="0" />
  </inertial>
  <visual >
   <origin  xyz="0.0 0.0 0.01" />
  </visual>
  <collision >
   <origin  xyz="0.0 0.0 0.01" />
  </collision>
 </link>
 <joint  name="Franka_research3_joint_5"  type="revolute" >
  <parent  link="Franka_research3_link_4" />
  <child  link="Franka_research3_link_5" />
  <origin  rpy="-1.5707963267948966 0.0 0.0"  xyz="-0.082504 0.123952 -0.0005" />
  <axis  xyz="0 0 1" />
  <limit  velocity="10"  lower="-2.88"  upper="2.88"  effort="300" />
 </joint>
 <link  name="Franka_research3_link_5" >
  <inertial >
   <origin  rpy="0.0 0.0 0.0"  xyz="0.0 0.0 0.0" />
   <mass  value="0.8" />
   <inertia  izz="0"  iyy="0"  ixz="0"  ixx="0"  iyz="0"  ixy="0" />
  </inertial>
  <visual >
   <origin  xyz="0.0 0.0 0.01" />
  </visual>
  <collision >
   <origin  xyz="0.0 0.0 0.01" />
  </collision>
 </link>
 <joint  name="Franka_research3_joint_6"  type="revolute" >
  <parent  link="Franka_research3_link_5" />
  <child  link="Franka_research3_link_6" />
  <origin  rpy="1.5707963267948966 -0.0 -2.220446049250313e-16"  xyz="0.0 0.016401 0.26" />
  <axis  xyz="0 0 1" />
  <limit  velocity="10"  lower="0.44"  upper="4.63"  effort="300" />
 </joint>
 <link  name="Franka_research3_link_6" >
  <inertial >
   <origin  rpy="0.0 0.0 0.0"  xyz="0.0 0.0 0.0" />
   <mass  value="0.8" />
   <inertia  izz="0"  iyy="0"  ixz="0"  ixx="0"  iyz="0"  ixy="0" />
  </inertial>
  <visual >
   <origin  xyz="0.0 0.0 -0.02" />
  </visual>
  <collision >
   <origin  xyz="0.0 0.0 -0.02" />
  </collision>
 </link>
 <joint  name="Franka_research3_joint_7"  type="revolute" >
  <parent  link="Franka_research3_link_6" />
  <child  link="Franka_research3_link_7" />
  <origin  rpy="1.5707963267948966 0.0 0.0"  xyz="0.088012 -0.05045 0.016429" />
  <axis  xyz="0 0 1" />
  <limit  velocity="10"  lower="-3.05"  upper="3.05"  effort="300" />
 </joint>
 <link  name="Franka_research3_link_7" >
  <inertial >
   <origin  rpy="0.0 0.0 0.0"  xyz="0.0 0.0 0.0" />
   <mass  value="0.8" />
   <inertia  izz="0"  iyy="0"  ixz="0"  ixx="0"  iyz="0"  ixy="0" />
  </inertial>
  <visual >
   <origin  xyz="0.0 0.0 -0.02" />
  </visual>
  <collision >
   <origin  xyz="0.0 0.0 -0.02" />
  </collision>
 </link>
</robot>
